2022-01-06 16:45:13 ERROR 400 response executing GraphQL.
2022-01-06 16:45:13 ERROR {"errors":[{"message":"Invalid sweep config: invalid hyperparameter configuration: model","path":["upsertSweep"]}],"data":{"upsertSweep":null}}
2022-01-06 16:45:13 ERROR Traceback (most recent call last):
  File "/opt/anaconda3/envs/py39/lib/python3.9/site-packages/wandb/sdk/lib/retry.py", line 102, in __call__
    result = self._call_fn(*args, **kwargs)
  File "/opt/anaconda3/envs/py39/lib/python3.9/site-packages/wandb/sdk/internal/internal_api.py", line 147, in execute
    six.reraise(*sys.exc_info())
  File "/opt/anaconda3/envs/py39/lib/python3.9/site-packages/six.py", line 719, in reraise
    raise value
  File "/opt/anaconda3/envs/py39/lib/python3.9/site-packages/wandb/sdk/internal/internal_api.py", line 141, in execute
    return self.client.execute(*args, **kwargs)
  File "/opt/anaconda3/envs/py39/lib/python3.9/site-packages/wandb/vendor/gql-0.2.0/gql/client.py", line 52, in execute
    result = self._get_result(document, *args, **kwargs)
  File "/opt/anaconda3/envs/py39/lib/python3.9/site-packages/wandb/vendor/gql-0.2.0/gql/client.py", line 60, in _get_result
    return self.transport.execute(document, *args, **kwargs)
  File "/opt/anaconda3/envs/py39/lib/python3.9/site-packages/wandb/vendor/gql-0.2.0/gql/transport/requests.py", line 39, in execute
    request.raise_for_status()
  File "/opt/anaconda3/envs/py39/lib/python3.9/site-packages/requests/models.py", line 953, in raise_for_status
    raise HTTPError(http_error_msg, response=self)
requests.exceptions.HTTPError: 400 Client Error: Bad Request for url: https://api.wandb.ai/graphql

During handling of the above exception, another exception occurred:

Traceback (most recent call last):
  File "/opt/anaconda3/envs/py39/lib/python3.9/site-packages/wandb/apis/normalize.py", line 24, in wrapper
    return func(*args, **kwargs)
  File "/opt/anaconda3/envs/py39/lib/python3.9/site-packages/wandb/sdk/internal/internal_api.py", line 1849, in upsert_sweep
    raise (e)
  File "/opt/anaconda3/envs/py39/lib/python3.9/site-packages/wandb/sdk/internal/internal_api.py", line 1835, in upsert_sweep
    response = self.gql(
  File "/opt/anaconda3/envs/py39/lib/python3.9/site-packages/wandb/sdk/lib/retry.py", line 118, in __call__
    if not check_retry_fn(e):
  File "/opt/anaconda3/envs/py39/lib/python3.9/site-packages/wandb/sdk/internal/internal_api.py", line 1826, in no_retry_4xx
    raise UsageError(body["errors"][0]["message"])
wandb.errors.UsageError: Invalid sweep config: invalid hyperparameter configuration: model

During handling of the above exception, another exception occurred:

Traceback (most recent call last):
  File "/opt/anaconda3/envs/py39/lib/python3.9/site-packages/wandb/cli/cli.py", line 86, in wrapper
    return func(*args, **kwargs)
  File "/opt/anaconda3/envs/py39/lib/python3.9/site-packages/wandb/cli/cli.py", line 856, in sweep
    sweep_id, warnings = api.upsert_sweep(
  File "/opt/anaconda3/envs/py39/lib/python3.9/site-packages/wandb/apis/internal.py", line 99, in upsert_sweep
    return self.api.upsert_sweep(*args, **kwargs)
  File "/opt/anaconda3/envs/py39/lib/python3.9/site-packages/wandb/apis/normalize.py", line 62, in wrapper
    six.reraise(CommError, CommError(message, err), sys.exc_info()[2])
  File "/opt/anaconda3/envs/py39/lib/python3.9/site-packages/six.py", line 718, in reraise
    raise value.with_traceback(tb)
  File "/opt/anaconda3/envs/py39/lib/python3.9/site-packages/wandb/apis/normalize.py", line 24, in wrapper
    return func(*args, **kwargs)
  File "/opt/anaconda3/envs/py39/lib/python3.9/site-packages/wandb/sdk/internal/internal_api.py", line 1849, in upsert_sweep
    raise (e)
  File "/opt/anaconda3/envs/py39/lib/python3.9/site-packages/wandb/sdk/internal/internal_api.py", line 1835, in upsert_sweep
    response = self.gql(
  File "/opt/anaconda3/envs/py39/lib/python3.9/site-packages/wandb/sdk/lib/retry.py", line 118, in __call__
    if not check_retry_fn(e):
  File "/opt/anaconda3/envs/py39/lib/python3.9/site-packages/wandb/sdk/internal/internal_api.py", line 1826, in no_retry_4xx
    raise UsageError(body["errors"][0]["message"])
wandb.errors.CommError: Invalid sweep config: invalid hyperparameter configuration: model

2022-01-06 16:50:02 ERROR 400 response executing GraphQL.
2022-01-06 16:50:02 ERROR {"errors":[{"message":"Invalid sweep config: invalid hyperparameter configuration: model","path":["upsertSweep"]}],"data":{"upsertSweep":null}}
2022-01-06 16:50:02 ERROR Traceback (most recent call last):
  File "/opt/anaconda3/envs/py39/lib/python3.9/site-packages/wandb/sdk/lib/retry.py", line 102, in __call__
    result = self._call_fn(*args, **kwargs)
  File "/opt/anaconda3/envs/py39/lib/python3.9/site-packages/wandb/sdk/internal/internal_api.py", line 147, in execute
    six.reraise(*sys.exc_info())
  File "/opt/anaconda3/envs/py39/lib/python3.9/site-packages/six.py", line 719, in reraise
    raise value
  File "/opt/anaconda3/envs/py39/lib/python3.9/site-packages/wandb/sdk/internal/internal_api.py", line 141, in execute
    return self.client.execute(*args, **kwargs)
  File "/opt/anaconda3/envs/py39/lib/python3.9/site-packages/wandb/vendor/gql-0.2.0/gql/client.py", line 52, in execute
    result = self._get_result(document, *args, **kwargs)
  File "/opt/anaconda3/envs/py39/lib/python3.9/site-packages/wandb/vendor/gql-0.2.0/gql/client.py", line 60, in _get_result
    return self.transport.execute(document, *args, **kwargs)
  File "/opt/anaconda3/envs/py39/lib/python3.9/site-packages/wandb/vendor/gql-0.2.0/gql/transport/requests.py", line 39, in execute
    request.raise_for_status()
  File "/opt/anaconda3/envs/py39/lib/python3.9/site-packages/requests/models.py", line 953, in raise_for_status
    raise HTTPError(http_error_msg, response=self)
requests.exceptions.HTTPError: 400 Client Error: Bad Request for url: https://api.wandb.ai/graphql

During handling of the above exception, another exception occurred:

Traceback (most recent call last):
  File "/opt/anaconda3/envs/py39/lib/python3.9/site-packages/wandb/apis/normalize.py", line 24, in wrapper
    return func(*args, **kwargs)
  File "/opt/anaconda3/envs/py39/lib/python3.9/site-packages/wandb/sdk/internal/internal_api.py", line 1849, in upsert_sweep
    raise (e)
  File "/opt/anaconda3/envs/py39/lib/python3.9/site-packages/wandb/sdk/internal/internal_api.py", line 1835, in upsert_sweep
    response = self.gql(
  File "/opt/anaconda3/envs/py39/lib/python3.9/site-packages/wandb/sdk/lib/retry.py", line 118, in __call__
    if not check_retry_fn(e):
  File "/opt/anaconda3/envs/py39/lib/python3.9/site-packages/wandb/sdk/internal/internal_api.py", line 1826, in no_retry_4xx
    raise UsageError(body["errors"][0]["message"])
wandb.errors.UsageError: Invalid sweep config: invalid hyperparameter configuration: model

During handling of the above exception, another exception occurred:

Traceback (most recent call last):
  File "/opt/anaconda3/envs/py39/lib/python3.9/site-packages/wandb/cli/cli.py", line 86, in wrapper
    return func(*args, **kwargs)
  File "/opt/anaconda3/envs/py39/lib/python3.9/site-packages/wandb/cli/cli.py", line 856, in sweep
    sweep_id, warnings = api.upsert_sweep(
  File "/opt/anaconda3/envs/py39/lib/python3.9/site-packages/wandb/apis/internal.py", line 99, in upsert_sweep
    return self.api.upsert_sweep(*args, **kwargs)
  File "/opt/anaconda3/envs/py39/lib/python3.9/site-packages/wandb/apis/normalize.py", line 62, in wrapper
    six.reraise(CommError, CommError(message, err), sys.exc_info()[2])
  File "/opt/anaconda3/envs/py39/lib/python3.9/site-packages/six.py", line 718, in reraise
    raise value.with_traceback(tb)
  File "/opt/anaconda3/envs/py39/lib/python3.9/site-packages/wandb/apis/normalize.py", line 24, in wrapper
    return func(*args, **kwargs)
  File "/opt/anaconda3/envs/py39/lib/python3.9/site-packages/wandb/sdk/internal/internal_api.py", line 1849, in upsert_sweep
    raise (e)
  File "/opt/anaconda3/envs/py39/lib/python3.9/site-packages/wandb/sdk/internal/internal_api.py", line 1835, in upsert_sweep
    response = self.gql(
  File "/opt/anaconda3/envs/py39/lib/python3.9/site-packages/wandb/sdk/lib/retry.py", line 118, in __call__
    if not check_retry_fn(e):
  File "/opt/anaconda3/envs/py39/lib/python3.9/site-packages/wandb/sdk/internal/internal_api.py", line 1826, in no_retry_4xx
    raise UsageError(body["errors"][0]["message"])
wandb.errors.CommError: Invalid sweep config: invalid hyperparameter configuration: model

2022-01-06 16:53:46 INFO Running runs: []
2022-01-06 16:53:47 INFO Agent received command: run
2022-01-06 16:53:47 INFO Agent starting run with config:
	batch_size: 32
	conv_to_linear_dim: 144
	epochs: 40
	hidden_channel_array: [4, 8, 16]
	hidden_dim_array: [50]
	hidden_kernel_array: [3, 3, 3]
	hidden_padding_array: [1, 1, 1]
	hidden_stride_array: [1, 1, 1]
	input_channel: 1
	lr: 0.001
	momentum: 0.95
	non_linear_function_array: []
	optimizer: adamw
	output_dim: 10
	regularization_array: []
	weight_decay: 0.02
2022-01-06 16:53:47 INFO About to run command: /usr/bin/env python src/models/train_model.py batch_size=32 conv_to_linear_dim=144 epochs=40 "hidden_channel_array=[4, 8, 16]" hidden_dim_array=[50] "hidden_kernel_array=[3, 3, 3]" "hidden_padding_array=[1, 1, 1]" "hidden_stride_array=[1, 1, 1]" input_channel=1 lr=0.001 momentum=0.95 non_linear_function_array=[] optimizer=adamw output_dim=10 regularization_array=[] weight_decay=0.02
2022-01-06 16:53:52 INFO Running runs: ['c4os7ryx']
