Traceback (most recent call last):
  File "/Users/weis/Documents/Skole/DTU/10_semester/ML_Ops/ML_Ops_Project_Repo/src/models/predict_model.py", line 125, in <module>
    main()
  File "/Users/weis/Documents/Skole/DTU/10_semester/ML_Ops/ML_Ops_Project_Repo/src/models/predict_model.py", line 115, in main
    my_table = wandb.Table(dataframe=res[0:500,])
  File "/opt/anaconda3/envs/py39/lib/python3.9/site-packages/pandas/core/frame.py", line 3458, in __getitem__
    indexer = self.columns.get_loc(key)
  File "/opt/anaconda3/envs/py39/lib/python3.9/site-packages/pandas/core/indexes/base.py", line 3361, in get_loc
    return self._engine.get_loc(casted_key)
  File "pandas/_libs/index.pyx", line 76, in pandas._libs.index.IndexEngine.get_loc
  File "pandas/_libs/index.pyx", line 82, in pandas._libs.index.IndexEngine.get_loc
TypeError: '(slice(0, 500, None),)' is an invalid key
Test accuracy is: 95.8800048828125%