Traceback (most recent call last):
  File "/Users/weis/Documents/Skole/DTU/10_semester/ML_Ops/ML_Ops_Project_Repo/src/models/train_model.py", line 174, in <module>
  File "/Users/weis/Documents/Skole/DTU/10_semester/ML_Ops/ML_Ops_Project_Repo/src/models/train_model.py", line 153, in train
  File "/opt/anaconda3/envs/py39/lib/python3.9/site-packages/torch/serialization.py", line 376, in save
    with _open_file_like(f, 'wb') as opened_file:
  File "/opt/anaconda3/envs/py39/lib/python3.9/site-packages/torch/serialization.py", line 230, in _open_file_like
    return _open_file(name_or_buffer, mode)
  File "/opt/anaconda3/envs/py39/lib/python3.9/site-packages/torch/serialization.py", line 211, in __init__
    super(_open_file, self).__init__(open(name, mode))
FileNotFoundError: [Errno 2] No such file or directory: 'models/fits/outputs/2022-01-06/14-01-52/CNNModuleVar.pth'